Workbook
Name кромка: Справочник!$K$4:$L$20
Name назКромки: Справочник!$K$4:$K$20
Name обозначениКромки: Справочник!$A$4:$D$20
Name прифуговка: Справочник!$L$4:$L$20

Sheet Базис
A1: №№ | B1: длина | C1: ширина | D1: кол-во | E1: направл | F1: L1 | G1: L2 | H1: W1 | I1: W2 | J1: примеч | K1: матер | L1: толщина
A2: =IF(ISBLANK('Список деталей'!C10),"",'Список деталей'!A10) -> 1 | B2: =IF(ISNUMBER('Список деталей'!C10), 'Список деталей'!C10, "") -> 100 | C2: =IF(ISNUMBER('Список деталей'!D10), 'Список деталей'!D10, "") -> 100 | D2: =IF(ISNUMBER('Список деталей'!E10), 'Список деталей'!E10, "") -> 1 | F2: =IF(ISBLANK('Список деталей'!F10),"",VLOOKUP('Список деталей'!F10,Справочник!$A$4:$D$11,4,0)) -> Х Х Х 1 Х Х Х | G2: =IF(ISBLANK('Список деталей'!G10),"",VLOOKUP('Список деталей'!G10,Справочник!$A$4:$D$11,4,0)) -> Х Х Х 1 Х Х Х | H2: =IF(ISBLANK('Список деталей'!H10),"",VLOOKUP('Список деталей'!H10,Справочник!$A$4:$D$11,4,0)) -> Х Х Х 1 Х Х Х | I2: =IF(ISBLANK('Список деталей'!I10),"",VLOOKUP('Список деталей'!I10,Справочник!$A$4:$D$11,4,0)) -> ___ 04 ___ | J2: =IF(ISBLANK('Список деталей'!K10),"",'Список деталей'!K10) | K2: =IF(ISNUMBER('Список деталей'!C10), 'Список деталей'!$B$5,"") -> лдсп фон бежевый | L2: =IF(ISNUMBER('Список деталей'!C10), 'Список деталей'!$I$4,"") -> 16
A3: =IF(ISBLANK('Список деталей'!C11),"",'Список деталей'!A11) -> 2 | B3: =IF(ISNUMBER('Список деталей'!C11), 'Список деталей'!C11, "") -> 699 | C3: =IF(ISNUMBER('Список деталей'!D11), 'Список деталей'!D11, "") -> 122 | D3: =IF(ISNUMBER('Список деталей'!E11), 'Список деталей'!E11, "") -> 2 | F3: =IF(ISBLANK('Список деталей'!F11),"",VLOOKUP('Список деталей'!F11,Справочник!$A$4:$D$11,4,0)) -> ___ 04 ___ | G3: =IF(ISBLANK('Список деталей'!G11),"",VLOOKUP('Список деталей'!G11,Справочник!$A$4:$D$11,4,0)) -> Х Х Х 1 Х Х Х | H3: =IF(ISBLANK('Список деталей'!H11),"",VLOOKUP('Список деталей'!H11,Справочник!$A$4:$D$11,4,0)) -> Х Х Х 1 Х Х Х | I3: =IF(ISBLANK('Список деталей'!I11),"",VLOOKUP('Список деталей'!I11,Справочник!$A$4:$D$11,4,0)) -> Х Х Х 1 Х Х Х | J3: =IF(ISBLANK('Список деталей'!K11),"",'Список деталей'!K11) | K3: =IF(ISNUMBER('Список деталей'!C11), 'Список деталей'!$B$5,"") -> лдсп фон бежевый | L3: =IF(ISNUMBER('Список деталей'!C11), 'Список деталей'!$I$4,"") -> 16
A4: =IF(ISBLANK('Список деталей'!C12),"",'Список деталей'!A12) -> 3 | B4: =IF(ISNUMBER('Список деталей'!C12), 'Список деталей'!C12, "") -> 200 | C4: =IF(ISNUMBER('Список деталей'!D12), 'Список деталей'!D12, "") -> 400 | D4: =IF(ISNUMBER('Список деталей'!E12), 'Список деталей'!E12, "") -> 2 | F4: =IF(ISBLANK('Список деталей'!F12),"",VLOOKUP('Список деталей'!F12,Справочник!$A$4:$D$11,4,0)) -> Х Х Х 1*35 Х Х Х | G4: =IF(ISBLANK('Список деталей'!G12),"",VLOOKUP('Список деталей'!G12,Справочник!$A$4:$D$11,4,0)) -> ___04 *35___ | H4: =IF(ISBLANK('Список деталей'!H12),"",VLOOKUP('Список деталей'!H12,Справочник!$A$4:$D$11,4,0)) -> Х Х Х 1*35 Х Х Х | I4: =IF(ISBLANK('Список деталей'!I12),"",VLOOKUP('Список деталей'!I12,Справочник!$A$4:$D$11,4,0)) -> Х Х Х 1*35 Х Х Х | J4: =IF(ISBLANK('Список деталей'!K12),"",'Список деталей'!K12) -> *32 | K4: =IF(ISNUMBER('Список деталей'!C12), 'Список деталей'!$B$5,"") -> лдсп фон бежевый | L4: =IF(ISNUMBER('Список деталей'!C12), 'Список деталей'!$I$4,"") -> 16
A5: =IF(ISBLANK('Список деталей'!C13),"",'Список деталей'!A13) -> 4 | B5: =IF(ISNUMBER('Список деталей'!C13), 'Список деталей'!C13, "") -> 383 | C5: =IF(ISNUMBER('Список деталей'!D13), 'Список деталей'!D13, "") -> 554 | D5: =IF(ISNUMBER('Список деталей'!E13), 'Список деталей'!E13, "") -> 2 | F5: =IF(ISBLANK('Список деталей'!F13),"",VLOOKUP('Список деталей'!F13,Справочник!$A$4:$D$11,4,0)) -> ___ 04 ___ | G5: =IF(ISBLANK('Список деталей'!G13),"",VLOOKUP('Список деталей'!G13,Справочник!$A$4:$D$11,4,0)) -> ___ 04 ___ | H5: =IF(ISBLANK('Список деталей'!H13),"",VLOOKUP('Список деталей'!H13,Справочник!$A$4:$D$11,4,0)) -> ___ 04 ___ | I5: =IF(ISBLANK('Список деталей'!I13),"",VLOOKUP('Список деталей'!I13,Справочник!$A$4:$D$11,4,0)) -> ___ 04 ___ | J5: =IF(ISBLANK('Список деталей'!K13),"",'Список деталей'!K13) | K5: =IF(ISNUMBER('Список деталей'!C13), 'Список деталей'!$B$5,"") -> лдсп фон бежевый | L5: =IF(ISNUMBER('Список деталей'!C13), 'Список деталей'!$I$4,"") -> 16
A6: =IF(ISBLANK('Список деталей'!C14),"",'Список деталей'!A14) -> 5 | B6: =IF(ISNUMBER('Список деталей'!C14), 'Список деталей'!C14, "") -> 367 | C6: =IF(ISNUMBER('Список деталей'!D14), 'Список деталей'!D14, "") -> 554 | D6: =IF(ISNUMBER('Список деталей'!E14), 'Список деталей'!E14, "") -> 2 | F6: =IF(ISBLANK('Список деталей'!F14),"",VLOOKUP('Список деталей'!F14,Справочник!$A$4:$D$11,4,0)) -> ___ 04 ___ | G6: =IF(ISBLANK('Список деталей'!G14),"",VLOOKUP('Список деталей'!G14,Справочник!$A$4:$D$11,4,0)) -> ___ 04 ___ | H6: =IF(ISBLANK('Список деталей'!H14),"",VLOOKUP('Список деталей'!H14,Справочник!$A$4:$D$11,4,0)) -> ___ 04 ___ | I6: =IF(ISBLANK('Список деталей'!I14),"",VLOOKUP('Список деталей'!I14,Справочник!$A$4:$D$11,4,0)) -> ___ 04 ___ | J6: =IF(ISBLANK('Список деталей'!K14),"",'Список деталей'!K14) -> радиус | K6: =IF(ISNUMBER('Список деталей'!C14), 'Список деталей'!$B$5,"") -> лдсп фон бежевый | L6: =IF(ISNUMBER('Список деталей'!C14), 'Список деталей'!$I$4,"") -> 16
A7: =IF(ISBLANK('Список деталей'!C15),"",'Список деталей'!A15) -> 6 | B7: =IF(ISNUMBER('Список деталей'!C15), 'Список деталей'!C15, "") -> 699 | C7: =IF(ISNUMBER('Список деталей'!D15), 'Список деталей'!D15, "") -> 155 | D7: =IF(ISNUMBER('Список деталей'!E15), 'Список деталей'!E15, "") -> 2 | F7: =IF(ISBLANK('Список деталей'!F15),"",VLOOKUP('Список деталей'!F15,Справочник!$A$4:$D$11,4,0)) -> Х Х Х 1 Х Х Х | G7: =IF(ISBLANK('Список деталей'!G15),"",VLOOKUP('Список деталей'!G15,Справочник!$A$4:$D$11,4,0)) -> Х Х Х 1 Х Х Х | H7: =IF(ISBLANK('Список деталей'!H15),"",VLOOKUP('Список деталей'!H15,Справочник!$A$4:$D$11,4,0)) -> Х Х Х 1 Х Х Х | I7: =IF(ISBLANK('Список деталей'!I15),"",VLOOKUP('Список деталей'!I15,Справочник!$A$4:$D$11,4,0)) -> ■ ■ ■2■ ■ ■ | J7: =IF(ISBLANK('Список деталей'!K15),"",'Список деталей'!K15) | K7: =IF(ISNUMBER('Список деталей'!C15), 'Список деталей'!$B$5,"") -> лдсп фон бежевый | L7: =IF(ISNUMBER('Список деталей'!C15), 'Список деталей'!$I$4,"") -> 16
A8: =IF(ISBLANK('Список деталей'!C16),"",'Список деталей'!A16) -> 7 | B8: =IF(ISNUMBER('Список деталей'!C16), 'Список деталей'!C16, "") -> 155 | C8: =IF(ISNUMBER('Список деталей'!D16), 'Список деталей'!D16, "") -> 441 | D8: =IF(ISNUMBER('Список деталей'!E16), 'Список деталей'!E16, "") -> 2 | F8: =IF(ISBLANK('Список деталей'!F16),"",VLOOKUP('Список деталей'!F16,Справочник!$A$4:$D$11,4,0)) -> Х Х Х 1 Х Х Х | G8: =IF(ISBLANK('Список деталей'!G16),"",VLOOKUP('Список деталей'!G16,Справочник!$A$4:$D$11,4,0)) -> ___ 04 ___ | H8: =IF(ISBLANK('Список деталей'!H16),"",VLOOKUP('Список деталей'!H16,Справочник!$A$4:$D$11,4,0)) -> ___ 04 ___ | I8: =IF(ISBLANK('Список деталей'!I16),"",VLOOKUP('Список деталей'!I16,Справочник!$A$4:$D$11,4,0)) -> ___ 04 ___ | J8: =IF(ISBLANK('Список деталей'!K16),"",'Список деталей'!K16) -> Косарез с кром, чертёж | K8: =IF(ISNUMBER('Список деталей'!C16), 'Список деталей'!$B$5,"") -> лдсп фон бежевый | L8: =IF(ISNUMBER('Список деталей'!C16), 'Список деталей'!$I$4,"") -> 16
A9: =IF(ISBLANK('Список деталей'!C17),"",'Список деталей'!A17) -> 8 | B9: =IF(ISNUMBER('Список деталей'!C17), 'Список деталей'!C17, "") -> 439 | C9: =IF(ISNUMBER('Список деталей'!D17), 'Список деталей'!D17, "") -> 154 | D9: =IF(ISNUMBER('Список деталей'!E17), 'Список деталей'!E17, "") -> 1 | F9: =IF(ISBLANK('Список деталей'!F17),"",VLOOKUP('Список деталей'!F17,Справочник!$A$4:$D$11,4,0)) -> ___ 04 ___ | G9: =IF(ISBLANK('Список деталей'!G17),"",VLOOKUP('Список деталей'!G17,Справочник!$A$4:$D$11,4,0)) -> ___ 04 ___ | H9: =IF(ISBLANK('Список деталей'!H17),"",VLOOKUP('Список деталей'!H17,Справочник!$A$4:$D$11,4,0)) -> ___ 04 ___ | I9: =IF(ISBLANK('Список деталей'!I17),"",VLOOKUP('Список деталей'!I17,Справочник!$A$4:$D$11,4,0)) -> ___ 04 ___ | J9: =IF(ISBLANK('Список деталей'!K17),"",'Список деталей'!K17) | K9: =IF(ISNUMBER('Список деталей'!C17), 'Список деталей'!$B$5,"") -> лдсп фон бежевый | L9: =IF(ISNUMBER('Список деталей'!C17), 'Список деталей'!$I$4,"") -> 16
A10: =IF(ISBLANK('Список деталей'!C18),"",'Список деталей'!A18) -> 9 | B10: =IF(ISNUMBER('Список деталей'!C18), 'Список деталей'!C18, "") -> 496 | C10: =IF(ISNUMBER('Список деталей'!D18), 'Список деталей'!D18, "") -> 126 | D10: =IF(ISNUMBER('Список деталей'!E18), 'Список деталей'!E18, "") -> 2 | F10: =IF(ISBLANK('Список деталей'!F18),"",VLOOKUP('Список деталей'!F18,Справочник!$A$4:$D$11,4,0)) -> Х Х Х 1*35 Х Х Х | G10: =IF(ISBLANK('Список деталей'!G18),"",VLOOKUP('Список деталей'!G18,Справочник!$A$4:$D$11,4,0)) -> ___04 *35___ | H10: =IF(ISBLANK('Список деталей'!H18),"",VLOOKUP('Список деталей'!H18,Справочник!$A$4:$D$11,4,0)) | I10: =IF(ISBLANK('Список деталей'!I18),"",VLOOKUP('Список деталей'!I18,Справочник!$A$4:$D$11,4,0)) | J10: =IF(ISBLANK('Список деталей'!K18),"",'Список деталей'!K18) -> СКЛ 456*86-2шт | K10: =IF(ISNUMBER('Список деталей'!C18), 'Список деталей'!$B$5,"") -> лдсп фон бежевый | L10: =IF(ISNUMBER('Список деталей'!C18), 'Список деталей'!$I$4,"") -> 16
A11: =IF(ISBLANK('Список деталей'!C19),"",'Список деталей'!A19) -> 10 | B11: =IF(ISNUMBER('Список деталей'!C19), 'Список деталей'!C19, "") -> 439 | C11: =IF(ISNUMBER('Список деталей'!D19), 'Список деталей'!D19, "") -> 84 | D11: =IF(ISNUMBER('Список деталей'!E19), 'Список деталей'!E19, "") -> 1 | F11: =IF(ISBLANK('Список деталей'!F19),"",VLOOKUP('Список деталей'!F19,Справочник!$A$4:$D$11,4,0)) -> ___ 04 ___ | G11: =IF(ISBLANK('Список деталей'!G19),"",VLOOKUP('Список деталей'!G19,Справочник!$A$4:$D$11,4,0)) -> ___ 04 ___ | H11: =IF(ISBLANK('Список деталей'!H19),"",VLOOKUP('Список деталей'!H19,Справочник!$A$4:$D$11,4,0)) -> ___ 04 ___ | I11: =IF(ISBLANK('Список деталей'!I19),"",VLOOKUP('Список деталей'!I19,Справочник!$A$4:$D$11,4,0)) -> ___ 04 ___ | J11: =IF(ISBLANK('Список деталей'!K19),"",'Список деталей'!K19) | K11: =IF(ISNUMBER('Список деталей'!C19), 'Список деталей'!$B$5,"") -> лдсп фон бежевый | L11: =IF(ISNUMBER('Список деталей'!C19), 'Список деталей'!$I$4,"") -> 16
A12: =IF(ISBLANK('Список деталей'!C20),"",'Список деталей'!A20) -> 11 | B12: =IF(ISNUMBER('Список деталей'!C20), 'Список деталей'!C20, "") -> 496 | C12: =IF(ISNUMBER('Список деталей'!D20), 'Список деталей'!D20, "") -> 172 | D12: =IF(ISNUMBER('Список деталей'!E20), 'Список деталей'!E20, "") -> 2 | F12: =IF(ISBLANK('Список деталей'!F20),"",VLOOKUP('Список деталей'!F20,Справочник!$A$4:$D$11,4,0)) -> Х Х Х 1 Х Х Х | G12: =IF(ISBLANK('Список деталей'!G20),"",VLOOKUP('Список деталей'!G20,Справочник!$A$4:$D$11,4,0)) -> ___ 04 ___ | H12: =IF(ISBLANK('Список деталей'!H20),"",VLOOKUP('Список деталей'!H20,Справочник!$A$4:$D$11,4,0)) -> ___ 04 ___ | I12: =IF(ISBLANK('Список деталей'!I20),"",VLOOKUP('Список деталей'!I20,Справочник!$A$4:$D$11,4,0)) -> ___ 04 ___ | J12: =IF(ISBLANK('Список деталей'!K20),"",'Список деталей'!K20) -> РПЛ до 56*2, докромить | K12: =IF(ISNUMBER('Список деталей'!C20), 'Список деталей'!$B$5,"") -> лдсп фон бежевый | L12: =IF(ISNUMBER('Список деталей'!C20), 'Список деталей'!$I$4,"") -> 16
A13: =IF(ISBLANK('Список деталей'!C21),"",'Список деталей'!A21) -> 12 | B13: =IF(ISNUMBER('Список деталей'!C21), 'Список деталей'!C21, "") -> 367 | C13: =IF(ISNUMBER('Список деталей'!D21), 'Список деталей'!D21, "") -> 69 | D13: =IF(ISNUMBER('Список деталей'!E21), 'Список деталей'!E21, "") -> 1 | F13: =IF(ISBLANK('Список деталей'!F21),"",VLOOKUP('Список деталей'!F21,Справочник!$A$4:$D$11,4,0)) -> ___ 04 ___ | G13: =IF(ISBLANK('Список деталей'!G21),"",VLOOKUP('Список деталей'!G21,Справочник!$A$4:$D$11,4,0)) -> Х Х Х 1 Х Х Х | H13: =IF(ISBLANK('Список деталей'!H21),"",VLOOKUP('Список деталей'!H21,Справочник!$A$4:$D$11,4,0)) -> ___ 04 ___ | I13: =IF(ISBLANK('Список деталей'!I21),"",VLOOKUP('Список деталей'!I21,Справочник!$A$4:$D$11,4,0)) -> ___ 04 ___ | J13: =IF(ISBLANK('Список деталей'!K21),"",'Список деталей'!K21) | K13: =IF(ISNUMBER('Список деталей'!C21), 'Список деталей'!$B$5,"") -> лдсп фон бежевый | L13: =IF(ISNUMBER('Список деталей'!C21), 'Список деталей'!$I$4,"") -> 16
... A186: =IF(ISBLANK('Список деталей'!C194),"",'Список деталей'!A194) | B186: =IF(ISNUMBER('Список деталей'!C194), 'Список деталей'!C194, "") | C186: =IF(ISNUMBER('Список деталей'!D194), 'Список деталей'!D194, "") | D186: =IF(ISNUMBER('Список деталей'!E194), 'Список деталей'!E194, "") | F186: =IF(ISBLANK('Список деталей'!F194),"",VLOOKUP('Список деталей'!F194,Справочник!$A$4:$D$11,4,0)) | G186: =IF(ISBLANK('Список деталей'!G194),"",VLOOKUP('Список деталей'!G194,Справочник!$A$4:$D$11,4,0)) | H186: =IF(ISBLANK('Список деталей'!H194),"",VLOOKUP('Список деталей'!H194,Справочник!$A$4:$D$11,4,0)) | I186: =IF(ISBLANK('Список деталей'!I194),"",VLOOKUP('Список деталей'!I194,Справочник!$A$4:$D$11,4,0)) | J186: =IF(ISBLANK('Список деталей'!K194),"",'Список деталей'!K194) | K186: =IF(ISNUMBER('Список деталей'!C194), 'Список деталей'!$B$5,"") | L186: =IF(ISNUMBER('Список деталей'!C194), 'Список деталей'!$I$4,"")

Sheet KDT2
A1: Позиция детали | B1: Наименование детали | C1: Наименование материала | D1: Толщина заг | E1: Кол-во | F1: Длина заг | G1: Ширина заг | H1: Примечание | I1: Кромка L1 | J1: Кромка L2 | K1: Кромка W1 | L1: Кромка W2 | M1: Паз L1 | N1: Паз L2 | O1: Паз W1 | P1: Паз W2 | Q1: Длина | R1: Ширина | S1: ПИЛ_длина | T1: ПИЛ_ширина | U1: примеч | V1: большая деталь | W1: считаем БД
A2: =IF(ISNUMBER('Список деталей'!A10), 'Список деталей'!A10, "") -> 1 | B2: =IF(ISBLANK('Список деталей'!B10),"",'Список деталей'!B10) -> Крыша | C2: =IF(ISNUMBER('Список деталей'!C10), $W$4,"") -> лдсп фон бежевый | D2: =IF(ISNUMBER('Список деталей'!C10), 'Список деталей'!$I$4,"") -> 16 | E2: =IF(ISNUMBER('Список деталей'!E10), 'Список деталей'!E10, "") -> 1 | F2: =IF(ISNUMBER('Список деталей'!C10), 'Список деталей'!C10, "") -> 100 | G2: =IF(ISNUMBER('Список деталей'!D10), 'Список деталей'!D10, "") -> 100 | H2: =U2&" "&M2&" "&N2&" "&O2&" "&P2 | I2: =IF(ISBLANK('Список деталей'!F10),"",VLOOKUP('Список деталей'!F10,обозначениКромки,4,0)) -> Х Х Х 1 Х Х Х | J2: =IF(ISBLANK('Список деталей'!G10),"",VLOOKUP('Список деталей'!G10,обозначениКромки,4,0)) -> Х Х Х 1 Х Х Х | K2: =IF(ISBLANK('Список деталей'!H10),"",VLOOKUP('Список деталей'!H10,обозначениКромки,4,0)) -> Х Х Х 1 Х Х Х | L2: =IF(ISBLANK('Список деталей'!I10),"",VLOOKUP('Список деталей'!I10,обозначениКромки,4,0)) -> ___ 04 ___ | M2: =IF(ISBLANK('Список деталей'!Y10),"",('Список деталей'!Y10)) | N2: =IF(ISBLANK('Список деталей'!Z10),"",('Список деталей'!Z10)) | O2: =IF(ISBLANK('Список деталей'!AA10),"",('Список деталей'!AA10)) | P2: =IF(ISBLANK('Список деталей'!AB10),"",('Список деталей'!AB10)) | Q2: =VLOOKUP(IF(ISBLANK('Список деталей'!H10)=TRUE,7,'Список деталей'!H10),кромка,2,0)+VLOOKUP(IF(ISBLANK('Список деталей'!I10)=TRUE,7,'Список деталей'!I10),кромка,2,0)+'Список деталей'!C10 -> 101.5 | R2: =VLOOKUP(IF(ISBLANK('Список деталей'!F10)=TRUE,7,'Список деталей'!F10),кромка,2,0)+VLOOKUP(IF(ISBLANK('Список деталей'!G10)=TRUE,7,'Список деталей'!G10),кромка,2,0)+'Список деталей'!D10 -> 102 | S2: =IF('Список деталей'!H10="",0,1)+IF('Список деталей'!I10="",0,1)+'Список деталей'!C10 -> 102 | T2: =IF('Список деталей'!F10="",0,1)+IF('Список деталей'!G10="",0,1)+'Список деталей'!D10 -> 102 | U2: =IF(ISBLANK('Список деталей'!K10),"",'Список деталей'!K10) | V2: =IF(AND('Список деталей'!C10>849,'Список деталей'!D10>849)=TRUE,1*'Список деталей'!E10,"") | W2: =SUM(V:V) -> 0 | X2: =IF(W2=0,"",W2&"шт")
A3: =IF(ISNUMBER('Список деталей'!A11), 'Список деталей'!A11, "") -> 2 | B3: =IF(ISBLANK('Список деталей'!B11),"",'Список деталей'!B11) -> стойка | C3: =IF(ISNUMBER('Список деталей'!C11), $W$4,"") -> лдсп фон бежевый | D3: =IF(ISNUMBER('Список деталей'!C11), 'Список деталей'!$I$4,"") -> 16 | E3: =IF(ISNUMBER('Список деталей'!E11), 'Список деталей'!E11, "") -> 2 | F3: =IF(ISNUMBER('Список деталей'!C11), 'Список деталей'!C11, "") -> 699 | G3: =IF(ISNUMBER('Список деталей'!D11), 'Список деталей'!D11, "") -> 122 | H3: =U3&" "&M3&" "&N3&" "&O3&" "&P3 | I3: =IF(ISBLANK('Список деталей'!F11),"",VLOOKUP('Список деталей'!F11,обозначениКромки,4,0)) -> ___ 04 ___ | J3: =IF(ISBLANK('Список деталей'!G11),"",VLOOKUP('Список деталей'!G11,обозначениКромки,4,0)) -> Х Х Х 1 Х Х Х | K3: =IF(ISBLANK('Список деталей'!H11),"",VLOOKUP('Список деталей'!H11,обозначениКромки,4,0)) -> Х Х Х 1 Х Х Х | L3: =IF(ISBLANK('Список деталей'!I11),"",VLOOKUP('Список деталей'!I11,обозначениКромки,4,0)) -> Х Х Х 1 Х Х Х | M3: =IF(ISBLANK('Список деталей'!Y11),"",('Список деталей'!Y11)) | N3: =IF(ISBLANK('Список деталей'!Z11),"",('Список деталей'!Z11)) | O3: =IF(ISBLANK('Список деталей'!AA11),"",('Список деталей'!AA11)) | P3: =IF(ISBLANK('Список деталей'!AB11),"",('Список деталей'!AB11)) | Q3: =VLOOKUP(IF(ISBLANK('Список деталей'!H11)=TRUE,7,'Список деталей'!H11),кромка,2,0)+VLOOKUP(IF(ISBLANK('Список деталей'!I11)=TRUE,7,'Список деталей'!I11),кромка,2,0)+'Список деталей'!C11 -> 701 | R3: =VLOOKUP(IF(ISBLANK('Список деталей'!F11)=TRUE,7,'Список деталей'!F11),кромка,2,0)+VLOOKUP(IF(ISBLANK('Список деталей'!G11)=TRUE,7,'Список деталей'!G11),кромка,2,0)+'Список деталей'!D11 -> 123.5 | S3: =IF('Список деталей'!H11="",0,1)+IF('Список деталей'!I11="",0,1)+'Список деталей'!C11 -> 701 | T3: =IF('Список деталей'!F11="",0,1)+IF('Список деталей'!G11="",0,1)+'Список деталей'!D11 -> 124 | U3: =IF(ISBLANK('Список деталей'!K11),"",'Список деталей'!K11) | V3: =IF(AND('Список деталей'!C11>849,'Список деталей'!D11>849)=TRUE,1*'Список деталей'!E11,"") | W3: Материал +БД
A4: =IF(ISNUMBER('Список деталей'!A12), 'Список деталей'!A12, "") -> 3 | B4: =IF(ISBLANK('Список деталей'!B12),"",'Список деталей'!B12) -> дно | C4: =IF(ISNUMBER('Список деталей'!C12), $W$4,"") -> лдсп фон бежевый | D4: =IF(ISNUMBER('Список деталей'!C12), 'Список деталей'!$I$4,"") -> 16 | E4: =IF(ISNUMBER('Список деталей'!E12), 'Список деталей'!E12, "") -> 2 | F4: =IF(ISNUMBER('Список деталей'!C12), 'Список деталей'!C12, "") -> 200 | G4: =IF(ISNUMBER('Список деталей'!D12), 'Список деталей'!D12, "") -> 400 | H4: =U4&" "&M4&" "&N4&" "&O4&" "&P4 -> *32 | I4: =IF(ISBLANK('Список деталей'!F12),"",VLOOKUP('Список деталей'!F12,обозначениКромки,4,0)) -> Х Х Х 1*35 Х Х Х | J4: =IF(ISBLANK('Список деталей'!G12),"",VLOOKUP('Список деталей'!G12,обозначениКромки,4,0)) -> ___04 *35___ | K4: =IF(ISBLANK('Список деталей'!H12),"",VLOOKUP('Список деталей'!H12,обозначениКромки,4,0)) -> Х Х Х 1*35 Х Х Х | L4: =IF(ISBLANK('Список деталей'!I12),"",VLOOKUP('Список деталей'!I12,обозначениКромки,4,0)) -> Х Х Х 1*35 Х Х Х | M4: =IF(ISBLANK('Список деталей'!Y12),"",('Список деталей'!Y12)) | N4: =IF(ISBLANK('Список деталей'!Z12),"",('Список деталей'!Z12)) | O4: =IF(ISBLANK('Список деталей'!AA12),"",('Список деталей'!AA12)) | P4: =IF(ISBLANK('Список деталей'!AB12),"",('Список деталей'!AB12)) | Q4: =VLOOKUP(IF(ISBLANK('Список деталей'!H12)=TRUE,7,'Список деталей'!H12),кромка,2,0)+VLOOKUP(IF(ISBLANK('Список деталей'!I12)=TRUE,7,'Список деталей'!I12),кромка,2,0)+'Список деталей'!C12 -> 202 | R4: =VLOOKUP(IF(ISBLANK('Список деталей'!F12)=TRUE,7,'Список деталей'!F12),кромка,2,0)+VLOOKUP(IF(ISBLANK('Список деталей'!G12)=TRUE,7,'Список деталей'!G12),кромка,2,0)+'Список деталей'!D12 -> 401.5 | S4: =IF('Список деталей'!H12="",0,1)+IF('Список деталей'!I12="",0,1)+'Список деталей'!C12 -> 202 | T4: =IF('Список деталей'!F12="",0,1)+IF('Список деталей'!G12="",0,1)+'Список деталей'!D12 -> 402 | U4: =IF(ISBLANK('Список деталей'!K12),"",'Список деталей'!K12) -> *32 | V4: =IF(AND('Список деталей'!C12>849,'Список деталей'!D12>849)=TRUE,1*'Список деталей'!E12,"") | W4: ='Список деталей'!$B$5&" "&IF(W2>0,"БОЛЬШАЯ ДЕТАЛЬ","")&" "&X2 -> лдсп фон бежевый
A5: =IF(ISNUMBER('Список деталей'!A13), 'Список деталей'!A13, "") -> 4 | B5: =IF(ISBLANK('Список деталей'!B13),"",'Список деталей'!B13) | C5: =IF(ISNUMBER('Список деталей'!C13), $W$4,"") -> лдсп фон бежевый | D5: =IF(ISNUMBER('Список деталей'!C13), 'Список деталей'!$I$4,"") -> 16 | E5: =IF(ISNUMBER('Список деталей'!E13), 'Список деталей'!E13, "") -> 2 | F5: =IF(ISNUMBER('Список деталей'!C13), 'Список деталей'!C13, "") -> 383 | G5: =IF(ISNUMBER('Список деталей'!D13), 'Список деталей'!D13, "") -> 554 | H5: =U5&" "&M5&" "&N5&" "&O5&" "&P5 | I5: =IF(ISBLANK('Список деталей'!F13),"",VLOOKUP('Список деталей'!F13,обозначениКромки,4,0)) -> ___ 04 ___ | J5: =IF(ISBLANK('Список деталей'!G13),"",VLOOKUP('Список деталей'!G13,обозначениКромки,4,0)) -> ___ 04 ___ | K5: =IF(ISBLANK('Список деталей'!H13),"",VLOOKUP('Список деталей'!H13,обозначениКромки,4,0)) -> ___ 04 ___ | L5: =IF(ISBLANK('Список деталей'!I13),"",VLOOKUP('Список деталей'!I13,обозначениКромки,4,0)) -> ___ 04 ___ | M5: =IF(ISBLANK('Список деталей'!Y13),"",('Список деталей'!Y13)) | N5: =IF(ISBLANK('Список деталей'!Z13),"",('Список деталей'!Z13)) | O5: =IF(ISBLANK('Список деталей'!AA13),"",('Список деталей'!AA13)) | P5: =IF(ISBLANK('Список деталей'!AB13),"",('Список деталей'!AB13)) | Q5: =VLOOKUP(IF(ISBLANK('Список деталей'!H13)=TRUE,7,'Список деталей'!H13),кромка,2,0)+VLOOKUP(IF(ISBLANK('Список деталей'!I13)=TRUE,7,'Список деталей'!I13),кромка,2,0)+'Список деталей'!C13 -> 384 | R5: =VLOOKUP(IF(ISBLANK('Список деталей'!F13)=TRUE,7,'Список деталей'!F13),кромка,2,0)+VLOOKUP(IF(ISBLANK('Список деталей'!G13)=TRUE,7,'Список деталей'!G13),кромка,2,0)+'Список деталей'!D13 -> 555 | S5: =IF('Список деталей'!H13="",0,1)+IF('Список деталей'!I13="",0,1)+'Список деталей'!C13 -> 385 | T5: =IF('Список деталей'!F13="",0,1)+IF('Список деталей'!G13="",0,1)+'Список деталей'!D13 -> 556 | U5: =IF(ISBLANK('Список деталей'!K13),"",'Список деталей'!K13) | V5: =IF(AND('Список деталей'!C13>849,'Список деталей'!D13>849)=TRUE,1*'Список деталей'!E13,"")
A6: =IF(ISNUMBER('Список деталей'!A14), 'Список деталей'!A14, "") -> 5 | B6: =IF(ISBLANK('Список деталей'!B14),"",'Список деталей'!B14) | C6: =IF(ISNUMBER('Список деталей'!C14), $W$4,"") -> лдсп фон бежевый | D6: =IF(ISNUMBER('Список деталей'!C14), 'Список деталей'!$I$4,"") -> 16 | E6: =IF(ISNUMBER('Список деталей'!E14), 'Список деталей'!E14, "") -> 2 | F6: =IF(ISNUMBER('Список деталей'!C14), 'Список деталей'!C14, "") -> 367 | G6: =IF(ISNUMBER('Список деталей'!D14), 'Список деталей'!D14, "") -> 554 | H6: =U6&" "&M6&" "&N6&" "&O6&" "&P6 -> радиус | I6: =IF(ISBLANK('Список деталей'!F14),"",VLOOKUP('Список деталей'!F14,обозначениКромки,4,0)) -> ___ 04 ___ | J6: =IF(ISBLANK('Список деталей'!G14),"",VLOOKUP('Список деталей'!G14,обозначениКромки,4,0)) -> ___ 04 ___ | K6: =IF(ISBLANK('Список деталей'!H14),"",VLOOKUP('Список деталей'!H14,обозначениКромки,4,0)) -> ___ 04 ___ | L6: =IF(ISBLANK('Список деталей'!I14),"",VLOOKUP('Список деталей'!I14,обозначениКромки,4,0)) -> ___ 04 ___ | M6: =IF(ISBLANK('Список деталей'!Y14),"",('Список деталей'!Y14)) | N6: =IF(ISBLANK('Список деталей'!Z14),"",('Список деталей'!Z14)) | O6: =IF(ISBLANK('Список деталей'!AA14),"",('Список деталей'!AA14)) | P6: =IF(ISBLANK('Список деталей'!AB14),"",('Список деталей'!AB14)) | Q6: =VLOOKUP(IF(ISBLANK('Список деталей'!H14)=TRUE,7,'Список деталей'!H14),кромка,2,0)+VLOOKUP(IF(ISBLANK('Список деталей'!I14)=TRUE,7,'Список деталей'!I14),кромка,2,0)+'Список деталей'!C14 -> 368 | R6: =VLOOKUP(IF(ISBLANK('Список деталей'!F14)=TRUE,7,'Список деталей'!F14),кромка,2,0)+VLOOKUP(IF(ISBLANK('Список деталей'!G14)=TRUE,7,'Список деталей'!G14),кромка,2,0)+'Список деталей'!D14 -> 555 | S6: =IF('Список деталей'!H14="",0,1)+IF('Список деталей'!I14="",0,1)+'Список деталей'!C14 -> 369 | T6: =IF('Список деталей'!F14="",0,1)+IF('Список деталей'!G14="",0,1)+'Список деталей'!D14 -> 556 | U6: =IF(ISBLANK('Список деталей'!K14),"",'Список деталей'!K14) -> радиус | V6: =IF(AND('Список деталей'!C14>849,'Список деталей'!D14>849)=TRUE,1*'Список деталей'!E14,"") | W6: =IF(W2>0,"БОЛЬШАЯ ДЕТАЛЬ","")
A7: =IF(ISNUMBER('Список деталей'!A15), 'Список деталей'!A15, "") -> 6 | B7: =IF(ISBLANK('Список деталей'!B15),"",'Список деталей'!B15) | C7: =IF(ISNUMBER('Список деталей'!C15), $W$4,"") -> лдсп фон бежевый | D7: =IF(ISNUMBER('Список деталей'!C15), 'Список деталей'!$I$4,"") -> 16 | E7: =IF(ISNUMBER('Список деталей'!E15), 'Список деталей'!E15, "") -> 2 | F7: =IF(ISNUMBER('Список деталей'!C15), 'Список деталей'!C15, "") -> 699 | G7: =IF(ISNUMBER('Список деталей'!D15), 'Список деталей'!D15, "") -> 155 | H7: =U7&" "&M7&" "&N7&" "&O7&" "&P7 | I7: =IF(ISBLANK('Список деталей'!F15),"",VLOOKUP('Список деталей'!F15,обозначениКромки,4,0)) -> Х Х Х 1 Х Х Х | J7: =IF(ISBLANK('Список деталей'!G15),"",VLOOKUP('Список деталей'!G15,обозначениКромки,4,0)) -> Х Х Х 1 Х Х Х | K7: =IF(ISBLANK('Список деталей'!H15),"",VLOOKUP('Список деталей'!H15,обозначениКромки,4,0)) -> Х Х Х 1 Х Х Х | L7: =IF(ISBLANK('Список деталей'!I15),"",VLOOKUP('Список деталей'!I15,обозначениКромки,4,0)) -> ■ ■ ■2■ ■ ■ | M7: =IF(ISBLANK('Список деталей'!Y15),"",('Список деталей'!Y15)) | N7: =IF(ISBLANK('Список деталей'!Z15),"",('Список деталей'!Z15)) | O7: =IF(ISBLANK('Список деталей'!AA15),"",('Список деталей'!AA15)) | P7: =IF(ISBLANK('Список деталей'!AB15),"",('Список деталей'!AB15)) | Q7: =VLOOKUP(IF(ISBLANK('Список деталей'!H15)=TRUE,7,'Список деталей'!H15),кромка,2,0)+VLOOKUP(IF(ISBLANK('Список деталей'!I15)=TRUE,7,'Список деталей'!I15),кромка,2,0)+'Список деталей'!C15 -> 702 | R7: =VLOOKUP(IF(ISBLANK('Список деталей'!F15)=TRUE,7,'Список деталей'!F15),кромка,2,0)+VLOOKUP(IF(ISBLANK('Список деталей'!G15)=TRUE,7,'Список деталей'!G15),кромка,2,0)+'Список деталей'!D15 -> 157 | S7: =IF('Список деталей'!H15="",0,1)+IF('Список деталей'!I15="",0,1)+'Список деталей'!C15 -> 701 | T7: =IF('Список деталей'!F15="",0,1)+IF('Список деталей'!G15="",0,1)+'Список деталей'!D15 -> 157 | U7: =IF(ISBLANK('Список деталей'!K15),"",'Список деталей'!K15) | V7: =IF(AND('Список деталей'!C15>849,'Список деталей'!D15>849)=TRUE,1*'Список деталей'!E15,"")
A8: =IF(ISNUMBER('Список деталей'!A16), 'Список деталей'!A16, "") -> 7 | B8: =IF(ISBLANK('Список деталей'!B16),"",'Список деталей'!B16) | C8: =IF(ISNUMBER('Список деталей'!C16), $W$4,"") -> лдсп фон бежевый | D8: =IF(ISNUMBER('Список деталей'!C16), 'Список деталей'!$I$4,"") -> 16 | E8: =IF(ISNUMBER('Список деталей'!E16), 'Список деталей'!E16, "") -> 2 | F8: =IF(ISNUMBER('Список деталей'!C16), 'Список деталей'!C16, "") -> 155 | G8: =IF(ISNUMBER('Список деталей'!D16), 'Список деталей'!D16, "") -> 441 | H8: =U8&" "&M8&" "&N8&" "&O8&" "&P8 -> Косарез с кром, чертёж | I8: =IF(ISBLANK('Список деталей'!F16),"",VLOOKUP('Список деталей'!F16,обозначениКромки,4,0)) -> Х Х Х 1 Х Х Х | J8: =IF(ISBLANK('Список деталей'!G16),"",VLOOKUP('Список деталей'!G16,обозначениКромки,4,0)) -> ___ 04 ___ | K8: =IF(ISBLANK('Список деталей'!H16),"",VLOOKUP('Список деталей'!H16,обозначениКромки,4,0)) -> ___ 04 ___ | L8: =IF(ISBLANK('Список деталей'!I16),"",VLOOKUP('Список деталей'!I16,обозначениКромки,4,0)) -> ___ 04 ___ | M8: =IF(ISBLANK('Список деталей'!Y16),"",('Список деталей'!Y16)) | N8: =IF(ISBLANK('Список деталей'!Z16),"",('Список деталей'!Z16)) | O8: =IF(ISBLANK('Список деталей'!AA16),"",('Список деталей'!AA16)) | P8: =IF(ISBLANK('Список деталей'!AB16),"",('Список деталей'!AB16)) | Q8: =VLOOKUP(IF(ISBLANK('Список деталей'!H16)=TRUE,7,'Список деталей'!H16),кромка,2,0)+VLOOKUP(IF(ISBLANK('Список деталей'!I16)=TRUE,7,'Список деталей'!I16),кромка,2,0)+'Список деталей'!C16 -> 156 | R8: =VLOOKUP(IF(ISBLANK('Список деталей'!F16)=TRUE,7,'Список деталей'!F16),кромка,2,0)+VLOOKUP(IF(ISBLANK('Список деталей'!G16)=TRUE,7,'Список деталей'!G16),кромка,2,0)+'Список деталей'!D16 -> 442.5 | S8: =IF('Список деталей'!H16="",0,1)+IF('Список деталей'!I16="",0,1)+'Список деталей'!C16 -> 157 | T8: =IF('Список деталей'!F16="",0,1)+IF('Список деталей'!G16="",0,1)+'Список деталей'!D16 -> 443 | U8: =IF(ISBLANK('Список деталей'!K16),"",'Список деталей'!K16) -> Косарез с кром, чертёж | V8: =IF(AND('Список деталей'!C16>849,'Список деталей'!D16>849)=TRUE,1*'Список деталей'!E16,"")
A9: =IF(ISNUMBER('Список деталей'!A17), 'Список деталей'!A17, "") -> 8 | B9: =IF(ISBLANK('Список деталей'!B17),"",'Список деталей'!B17) | C9: =IF(ISNUMBER('Список деталей'!C17), $W$4,"") -> лдсп фон бежевый | D9: =IF(ISNUMBER('Список деталей'!C17), 'Список деталей'!$I$4,"") -> 16 | E9: =IF(ISNUMBER('Список деталей'!E17), 'Список деталей'!E17, "") -> 1 | F9: =IF(ISNUMBER('Список деталей'!C17), 'Список деталей'!C17, "") -> 439 | G9: =IF(ISNUMBER('Список деталей'!D17), 'Список деталей'!D17, "") -> 154 | H9: =U9&" "&M9&" "&N9&" "&O9&" "&P9 | I9: =IF(ISBLANK('Список деталей'!F17),"",VLOOKUP('Список деталей'!F17,обозначениКромки,4,0)) -> ___ 04 ___ | J9: =IF(ISBLANK('Список деталей'!G17),"",VLOOKUP('Список деталей'!G17,обозначениКромки,4,0)) -> ___ 04 ___ | K9: =IF(ISBLANK('Список деталей'!H17),"",VLOOKUP('Список деталей'!H17,обозначениКромки,4,0)) -> ___ 04 ___ | L9: =IF(ISBLANK('Список деталей'!I17),"",VLOOKUP('Список деталей'!I17,обозначениКромки,4,0)) -> ___ 04 ___ | M9: =IF(ISBLANK('Список деталей'!Y17),"",('Список деталей'!Y17)) | N9: =IF(ISBLANK('Список деталей'!Z17),"",('Список деталей'!Z17)) | O9: =IF(ISBLANK('Список деталей'!AA17),"",('Список деталей'!AA17)) | P9: =IF(ISBLANK('Список деталей'!AB17),"",('Список деталей'!AB17)) | Q9: =VLOOKUP(IF(ISBLANK('Список деталей'!H17)=TRUE,7,'Список деталей'!H17),кромка,2,0)+VLOOKUP(IF(ISBLANK('Список деталей'!I17)=TRUE,7,'Список деталей'!I17),кромка,2,0)+'Список деталей'!C17 -> 440 | R9: =VLOOKUP(IF(ISBLANK('Список деталей'!F17)=TRUE,7,'Список деталей'!F17),кромка,2,0)+VLOOKUP(IF(ISBLANK('Список деталей'!G17)=TRUE,7,'Список деталей'!G17),кромка,2,0)+'Список деталей'!D17 -> 155 | S9: =IF('Список деталей'!H17="",0,1)+IF('Список деталей'!I17="",0,1)+'Список деталей'!C17 -> 441 | T9: =IF('Список деталей'!F17="",0,1)+IF('Список деталей'!G17="",0,1)+'Список деталей'!D17 -> 156 | U9: =IF(ISBLANK('Список деталей'!K17),"",'Список деталей'!K17) | V9: =IF(AND('Список деталей'!C17>849,'Список деталей'!D17>849)=TRUE,1*'Список деталей'!E17,"")
A10: =IF(ISNUMBER('Список деталей'!A18), 'Список деталей'!A18, "") -> 9 | B10: =IF(ISBLANK('Список деталей'!B18),"",'Список деталей'!B18) | C10: =IF(ISNUMBER('Список деталей'!C18), $W$4,"") -> лдсп фон бежевый | D10: =IF(ISNUMBER('Список деталей'!C18), 'Список деталей'!$I$4,"") -> 16 | E10: =IF(ISNUMBER('Список деталей'!E18), 'Список деталей'!E18, "") -> 2 | F10: =IF(ISNUMBER('Список деталей'!C18), 'Список деталей'!C18, "") -> 496 | G10: =IF(ISNUMBER('Список деталей'!D18), 'Список деталей'!D18, "") -> 126 | H10: =U10&" "&M10&" "&N10&" "&O10&" "&P10 -> СКЛ 456*86-2шт | I10: =IF(ISBLANK('Список деталей'!F18),"",VLOOKUP('Список деталей'!F18,обозначениКромки,4,0)) -> Х Х Х 1*35 Х Х Х | J10: =IF(ISBLANK('Список деталей'!G18),"",VLOOKUP('Список деталей'!G18,обозначениКромки,4,0)) -> ___04 *35___ | K10: =IF(ISBLANK('Список деталей'!H18),"",VLOOKUP('Список деталей'!H18,обозначениКромки,4,0)) | L10: =IF(ISBLANK('Список деталей'!I18),"",VLOOKUP('Список деталей'!I18,обозначениКромки,4,0)) | M10: =IF(ISBLANK('Список деталей'!Y18),"",('Список деталей'!Y18)) | N10: =IF(ISBLANK('Список деталей'!Z18),"",('Список деталей'!Z18)) | O10: =IF(ISBLANK('Список деталей'!AA18),"",('Список деталей'!AA18)) | P10: =IF(ISBLANK('Список деталей'!AB18),"",('Список деталей'!AB18)) | Q10: =VLOOKUP(IF(ISBLANK('Список деталей'!H18)=TRUE,7,'Список деталей'!H18),кромка,2,0)+VLOOKUP(IF(ISBLANK('Список деталей'!I18)=TRUE,7,'Список деталей'!I18),кромка,2,0)+'Список деталей'!C18 -> 496 | R10: =VLOOKUP(IF(ISBLANK('Список деталей'!F18)=TRUE,7,'Список деталей'!F18),кромка,2,0)+VLOOKUP(IF(ISBLANK('Список деталей'!G18)=TRUE,7,'Список деталей'!G18),кромка,2,0)+'Список деталей'!D18 -> 127.5 | S10: =IF('Список деталей'!H18="",0,1)+IF('Список деталей'!I18="",0,1)+'Список деталей'!C18 -> 496 | T10: =IF('Список деталей'!F18="",0,1)+IF('Список деталей'!G18="",0,1)+'Список деталей'!D18 -> 128 | U10: =IF(ISBLANK('Список деталей'!K18),"",'Список деталей'!K18) -> СКЛ 456*86-2шт | V10: =IF(AND('Список деталей'!C18>849,'Список деталей'!D18>849)=TRUE,1*'Список деталей'!E18,"")
A11: =IF(ISNUMBER('Список деталей'!A19), 'Список деталей'!A19, "") -> 10 | B11: =IF(ISBLANK('Список деталей'!B19),"",'Список деталей'!B19) | C11: =IF(ISNUMBER('Список деталей'!C19), $W$4,"") -> лдсп фон бежевый | D11: =IF(ISNUMBER('Список деталей'!C19), 'Список деталей'!$I$4,"") -> 16 | E11: =IF(ISNUMBER('Список деталей'!E19), 'Список деталей'!E19, "") -> 1 | F11: =IF(ISNUMBER('Список деталей'!C19), 'Список деталей'!C19, "") -> 439 | G11: =IF(ISNUMBER('Список деталей'!D19), 'Список деталей'!D19, "") -> 84 | H11: =U11&" "&M11&" "&N11&" "&O11&" "&P11 | I11: =IF(ISBLANK('Список деталей'!F19),"",VLOOKUP('Список деталей'!F19,обозначениКромки,4,0)) -> ___ 04 ___ | J11: =IF(ISBLANK('Список деталей'!G19),"",VLOOKUP('Список деталей'!G19,обозначениКромки,4,0)) -> ___ 04 ___ | K11: =IF(ISBLANK('Список деталей'!H19),"",VLOOKUP('Список деталей'!H19,обозначениКромки,4,0)) -> ___ 04 ___ | L11: =IF(ISBLANK('Список деталей'!I19),"",VLOOKUP('Список деталей'!I19,обозначениКромки,4,0)) -> ___ 04 ___ | M11: =IF(ISBLANK('Список деталей'!Y19),"",('Список деталей'!Y19)) | N11: =IF(ISBLANK('Список деталей'!Z19),"",('Список деталей'!Z19)) | O11: =IF(ISBLANK('Список деталей'!AA19),"",('Список деталей'!AA19)) | P11: =IF(ISBLANK('Список деталей'!AB19),"",('Список деталей'!AB19)) | Q11: =VLOOKUP(IF(ISBLANK('Список деталей'!H19)=TRUE,7,'Список деталей'!H19),кромка,2,0)+VLOOKUP(IF(ISBLANK('Список деталей'!I19)=TRUE,7,'Список деталей'!I19),кромка,2,0)+'Список деталей'!C19 -> 440 | R11: =VLOOKUP(IF(ISBLANK('Список деталей'!F19)=TRUE,7,'Список деталей'!F19),кромка,2,0)+VLOOKUP(IF(ISBLANK('Список деталей'!G19)=TRUE,7,'Список деталей'!G19),кромка,2,0)+'Список деталей'!D19 -> 85 | S11: =IF('Список деталей'!H19="",0,1)+IF('Список деталей'!I19="",0,1)+'Список деталей'!C19 -> 441 | T11: =IF('Список деталей'!F19="",0,1)+IF('Список деталей'!G19="",0,1)+'Список деталей'!D19 -> 86 | U11: =IF(ISBLANK('Список деталей'!K19),"",'Список деталей'!K19) | V11: =IF(AND('Список деталей'!C19>849,'Список деталей'!D19>849)=TRUE,1*'Список деталей'!E19,"")
A12: =IF(ISNUMBER('Список деталей'!A20), 'Список деталей'!A20, "") -> 11 | B12: =IF(ISBLANK('Список деталей'!B20),"",'Список деталей'!B20) | C12: =IF(ISNUMBER('Список деталей'!C20), $W$4,"") -> лдсп фон бежевый | D12: =IF(ISNUMBER('Список деталей'!C20), 'Список деталей'!$I$4,"") -> 16 | E12: =IF(ISNUMBER('Список деталей'!E20), 'Список деталей'!E20, "") -> 2 | F12: =IF(ISNUMBER('Список деталей'!C20), 'Список деталей'!C20, "") -> 496 | G12: =IF(ISNUMBER('Список деталей'!D20), 'Список деталей'!D20, "") -> 172 | H12: =U12&" "&M12&" "&N12&" "&O12&" "&P12 -> РПЛ до 56*2, докромить | I12: =IF(ISBLANK('Список деталей'!F20),"",VLOOKUP('Список деталей'!F20,обозначениКромки,4,0)) -> Х Х Х 1 Х Х Х | J12: =IF(ISBLANK('Список деталей'!G20),"",VLOOKUP('Список деталей'!G20,обозначениКромки,4,0)) -> ___ 04 ___ | K12: =IF(ISBLANK('Список деталей'!H20),"",VLOOKUP('Список деталей'!H20,обозначениКромки,4,0)) -> ___ 04 ___ | L12: =IF(ISBLANK('Список деталей'!I20),"",VLOOKUP('Список деталей'!I20,обозначениКромки,4,0)) -> ___ 04 ___ | M12: =IF(ISBLANK('Список деталей'!Y20),"",('Список деталей'!Y20)) | N12: =IF(ISBLANK('Список деталей'!Z20),"",('Список деталей'!Z20)) | O12: =IF(ISBLANK('Список деталей'!AA20),"",('Список деталей'!AA20)) | P12: =IF(ISBLANK('Список деталей'!AB20),"",('Список деталей'!AB20)) | Q12: =VLOOKUP(IF(ISBLANK('Список деталей'!H20)=TRUE,7,'Список деталей'!H20),кромка,2,0)+VLOOKUP(IF(ISBLANK('Список деталей'!I20)=TRUE,7,'Список деталей'!I20),кромка,2,0)+'Список деталей'!C20 -> 497 | R12: =VLOOKUP(IF(ISBLANK('Список деталей'!F20)=TRUE,7,'Список деталей'!F20),кромка,2,0)+VLOOKUP(IF(ISBLANK('Список деталей'!G20)=TRUE,7,'Список деталей'!G20),кромка,2,0)+'Список деталей'!D20 -> 173.5 | S12: =IF('Список деталей'!H20="",0,1)+IF('Список деталей'!I20="",0,1)+'Список деталей'!C20 -> 498 | T12: =IF('Список деталей'!F20="",0,1)+IF('Список деталей'!G20="",0,1)+'Список деталей'!D20 -> 174 | U12: =IF(ISBLANK('Список деталей'!K20),"",'Список деталей'!K20) -> РПЛ до 56*2, докромить | V12: =IF(AND('Список деталей'!C20>849,'Список деталей'!D20>849)=TRUE,1*'Список деталей'!E20,"")
A13: =IF(ISNUMBER('Список деталей'!A21), 'Список деталей'!A21, "") -> 12 | B13: =IF(ISBLANK('Список деталей'!B21),"",'Список деталей'!B21) | C13: =IF(ISNUMBER('Список деталей'!C21), $W$4,"") -> лдсп фон бежевый | D13: =IF(ISNUMBER('Список деталей'!C21), 'Список деталей'!$I$4,"") -> 16 | E13: =IF(ISNUMBER('Список деталей'!E21), 'Список деталей'!E21, "") -> 1 | F13: =IF(ISNUMBER('Список деталей'!C21), 'Список деталей'!C21, "") -> 367 | G13: =IF(ISNUMBER('Список деталей'!D21), 'Список деталей'!D21, "") -> 69 | H13: =U13&" "&M13&" "&N13&" "&O13&" "&P13 | I13: =IF(ISBLANK('Список деталей'!F21),"",VLOOKUP('Список деталей'!F21,обозначениКромки,4,0)) -> ___ 04 ___ | J13: =IF(ISBLANK('Список деталей'!G21),"",VLOOKUP('Список деталей'!G21,обозначениКромки,4,0)) -> Х Х Х 1 Х Х Х | K13: =IF(ISBLANK('Список деталей'!H21),"",VLOOKUP('Список деталей'!H21,обозначениКромки,4,0)) -> ___ 04 ___ | L13: =IF(ISBLANK('Список деталей'!I21),"",VLOOKUP('Список деталей'!I21,обозначениКромки,4,0)) -> ___ 04 ___ | M13: =IF(ISBLANK('Список деталей'!Y21),"",('Список деталей'!Y21)) | N13: =IF(ISBLANK('Список деталей'!Z21),"",('Список деталей'!Z21)) | O13: =IF(ISBLANK('Список деталей'!AA21),"",('Список деталей'!AA21)) | P13: =IF(ISBLANK('Список деталей'!AB21),"",('Список деталей'!AB21)) | Q13: =VLOOKUP(IF(ISBLANK('Список деталей'!H21)=TRUE,7,'Список деталей'!H21),кромка,2,0)+VLOOKUP(IF(ISBLANK('Список деталей'!I21)=TRUE,7,'Список деталей'!I21),кромка,2,0)+'Список деталей'!C21 -> 368 | R13: =VLOOKUP(IF(ISBLANK('Список деталей'!F21)=TRUE,7,'Список деталей'!F21),кромка,2,0)+VLOOKUP(IF(ISBLANK('Список деталей'!G21)=TRUE,7,'Список деталей'!G21),кромка,2,0)+'Список деталей'!D21 -> 70.5 | S13: =IF('Список деталей'!H21="",0,1)+IF('Список деталей'!I21="",0,1)+'Список деталей'!C21 -> 369 | T13: =IF('Список деталей'!F21="",0,1)+IF('Список деталей'!G21="",0,1)+'Список деталей'!D21 -> 71 | U13: =IF(ISBLANK('Список деталей'!K21),"",'Список деталей'!K21) | V13: =IF(AND('Список деталей'!C21>849,'Список деталей'!D21>849)=TRUE,1*'Список деталей'!E21,"")
A14: =IF(ISNUMBER('Список деталей'!A22), 'Список деталей'!A22, "") -> 13 | B14: =IF(ISBLANK('Список деталей'!B22),"",'Список деталей'!B22) | C14: =IF(ISNUMBER('Список деталей'!C22), $W$4,"") -> лдсп фон бежевый | D14: =IF(ISNUMBER('Список деталей'!C22), 'Список деталей'!$I$4,"") -> 16 | E14: =IF(ISNUMBER('Список деталей'!E22), 'Список деталей'!E22, "") -> 1 | F14: =IF(ISNUMBER('Список деталей'!C22), 'Список деталей'!C22, "") -> 100 | G14: =IF(ISNUMBER('Список деталей'!D22), 'Список деталей'!D22, "") -> 1000 | H14: =U14&" "&M14&" "&N14&" "&O14&" "&P14 | I14: =IF(ISBLANK('Список деталей'!F22),"",VLOOKUP('Список деталей'!F22,обозначениКромки,4,0)) | J14: =IF(ISBLANK('Список деталей'!G22),"",VLOOKUP('Список деталей'!G22,обозначениКромки,4,0)) | K14: =IF(ISBLANK('Список деталей'!H22),"",VLOOKUP('Список деталей'!H22,обозначениКромки,4,0)) | L14: =IF(ISBLANK('Список деталей'!I22),"",VLOOKUP('Список деталей'!I22,обозначениКромки,4,0)) | M14: =IF(ISBLANK('Список деталей'!Y22),"",('Список деталей'!Y22)) | N14: =IF(ISBLANK('Список деталей'!Z22),"",('Список деталей'!Z22)) | O14: =IF(ISBLANK('Список деталей'!AA22),"",('Список деталей'!AA22)) | P14: =IF(ISBLANK('Список деталей'!AB22),"",('Список деталей'!AB22)) | Q14: =VLOOKUP(IF(ISBLANK('Список деталей'!H22)=TRUE,7,'Список деталей'!H22),кромка,2,0)+VLOOKUP(IF(ISBLANK('Список деталей'!I22)=TRUE,7,'Список деталей'!I22),кромка,2,0)+'Список деталей'!C22 -> 100 | R14: =VLOOKUP(IF(ISBLANK('Список деталей'!F22)=TRUE,7,'Список деталей'!F22),кромка,2,0)+VLOOKUP(IF(ISBLANK('Список деталей'!G22)=TRUE,7,'Список деталей'!G22),кромка,2,0)+'Список деталей'!D22 -> 1000 | S14: =IF('Список деталей'!H22="",0,1)+IF('Список деталей'!I22="",0,1)+'Список деталей'!C22 -> 100 | T14: =IF('Список деталей'!F22="",0,1)+IF('Список деталей'!G22="",0,1)+'Список деталей'!D22 -> 1000 | U14: =IF(ISBLANK('Список деталей'!K22),"",'Список деталей'!K22) | V14: =IF(AND('Список деталей'!C22>849,'Список деталей'!D22>849)=TRUE,1*'Список деталей'!E22,"")
A15: =IF(ISNUMBER('Список деталей'!A23), 'Список деталей'!A23, "") -> 14 | B15: =IF(ISBLANK('Список деталей'!B23),"",'Список деталей'!B23) | C15: =IF(ISNUMBER('Список деталей'!C23), $W$4,"") | D15: =IF(ISNUMBER('Список деталей'!C23), 'Список деталей'!$I$4,"") | E15: =IF(ISNUMBER('Список деталей'!E23), 'Список деталей'!E23, "") | F15: =IF(ISNUMBER('Список деталей'!C23), 'Список деталей'!C23, "") | G15: =IF(ISNUMBER('Список деталей'!D23), 'Список деталей'!D23, "") | H15: =U15&" "&M15&" "&N15&" "&O15&" "&P15 | I15: =IF(ISBLANK('Список деталей'!F23),"",VLOOKUP('Список деталей'!F23,обозначениКромки,4,0)) | J15: =IF(ISBLANK('Список деталей'!G23),"",VLOOKUP('Список деталей'!G23,обозначениКромки,4,0)) | K15: =IF(ISBLANK('Список деталей'!H23),"",VLOOKUP('Список деталей'!H23,обозначениКромки,4,0)) | L15: =IF(ISBLANK('Список деталей'!I23),"",VLOOKUP('Список деталей'!I23,обозначениКромки,4,0)) | M15: =IF(ISBLANK('Список деталей'!Y23),"",('Список деталей'!Y23)) | N15: =IF(ISBLANK('Список деталей'!Z23),"",('Список деталей'!Z23)) | O15: =IF(ISBLANK('Список деталей'!AA23),"",('Список деталей'!AA23)) | P15: =IF(ISBLANK('Список деталей'!AB23),"",('Список деталей'!AB23)) | Q15: =VLOOKUP(IF(ISBLANK('Список деталей'!H23)=TRUE,7,'Список деталей'!H23),кромка,2,0)+VLOOKUP(IF(ISBLANK('Список деталей'!I23)=TRUE,7,'Список деталей'!I23),кромка,2,0)+'Список деталей'!C23 -> 0 | R15: =VLOOKUP(IF(ISBLANK('Список деталей'!F23)=TRUE,7,'Список деталей'!F23),кромка,2,0)+VLOOKUP(IF(ISBLANK('Список деталей'!G23)=TRUE,7,'Список деталей'!G23),кромка,2,0)+'Список деталей'!D23 -> 0 | S15: =IF('Список деталей'!H23="",0,1)+IF('Список деталей'!I23="",0,1)+'Список деталей'!C23 -> 0 | T15: =IF('Список деталей'!F23="",0,1)+IF('Список деталей'!G23="",0,1)+'Список деталей'!D23 -> 0 | U15: =IF(ISBLANK('Список деталей'!K23),"",'Список деталей'!K23) | V15: =IF(AND('Список деталей'!C23>849,'Список деталей'!D23>849)=TRUE,1*'Список деталей'!E23,"")
A16: =IF(ISNUMBER('Список деталей'!A24), 'Список деталей'!A24, "") -> 15 | B16: =IF(ISBLANK('Список деталей'!B24),"",'Список деталей'!B24) | C16: =IF(ISNUMBER('Список деталей'!C24), $W$4,"") | D16: =IF(ISNUMBER('Список деталей'!C24), 'Список деталей'!$I$4,"") | E16: =IF(ISNUMBER('Список деталей'!E24), 'Список деталей'!E24, "") | F16: =IF(ISNUMBER('Список деталей'!C24), 'Список деталей'!C24, "") | G16: =IF(ISNUMBER('Список деталей'!D24), 'Список деталей'!D24, "") | H16: =U16&" "&M16&" "&N16&" "&O16&" "&P16 | I16: =IF(ISBLANK('Список деталей'!F24),"",VLOOKUP('Список деталей'!F24,обозначениКромки,4,0)) | J16: =IF(ISBLANK('Список деталей'!G24),"",VLOOKUP('Список деталей'!G24,обозначениКромки,4,0)) | K16: =IF(ISBLANK('Список деталей'!H24),"",VLOOKUP('Список деталей'!H24,обозначениКромки,4,0)) | L16: =IF(ISBLANK('Список деталей'!I24),"",VLOOKUP('Список деталей'!I24,обозначениКромки,4,0)) | M16: =IF(ISBLANK('Список деталей'!Y24),"",('Список деталей'!Y24)) | N16: =IF(ISBLANK('Список деталей'!Z24),"",('Список деталей'!Z24)) | O16: =IF(ISBLANK('Список деталей'!AA24),"",('Список деталей'!AA24)) | P16: =IF(ISBLANK('Список деталей'!AB24),"",('Список деталей'!AB24)) | Q16: =VLOOKUP(IF(ISBLANK('Список деталей'!H24)=TRUE,7,'Список деталей'!H24),кромка,2,0)+VLOOKUP(IF(ISBLANK('Список деталей'!I24)=TRUE,7,'Список деталей'!I24),кромка,2,0)+'Список деталей'!C24 -> 0 | R16: =VLOOKUP(IF(ISBLANK('Список деталей'!F24)=TRUE,7,'Список деталей'!F24),кромка,2,0)+VLOOKUP(IF(ISBLANK('Список деталей'!G24)=TRUE,7,'Список деталей'!G24),кромка,2,0)+'Список деталей'!D24 -> 0 | S16: =IF('Список деталей'!H24="",0,1)+IF('Список деталей'!I24="",0,1)+'Список деталей'!C24 -> 0 | T16: =IF('Список деталей'!F24="",0,1)+IF('Список деталей'!G24="",0,1)+'Список деталей'!D24 -> 0 | U16: =IF(ISBLANK('Список деталей'!K24),"",'Список деталей'!K24) | V16: =IF(AND('Список деталей'!C24>849,'Список деталей'!D24>849)=TRUE,1*'Список деталей'!E24,"")
A17: =IF(ISNUMBER('Список деталей'!A25), 'Список деталей'!A25, "") -> 16 | B17: =IF(ISBLANK('Список деталей'!B25),"",'Список деталей'!B25) | C17: =IF(ISNUMBER('Список деталей'!C25), $W$4,"") | D17: =IF(ISNUMBER('Список деталей'!C25), 'Список деталей'!$I$4,"") | E17: =IF(ISNUMBER('Список деталей'!E25), 'Список деталей'!E25, "") | F17: =IF(ISNUMBER('Список деталей'!C25), 'Список деталей'!C25, "") | G17: =IF(ISNUMBER('Список деталей'!D25), 'Список деталей'!D25, "") | H17: =U17&" "&M17&" "&N17&" "&O17&" "&P17 | I17: =IF(ISBLANK('Список деталей'!F25),"",VLOOKUP('Список деталей'!F25,обозначениКромки,4,0)) | J17: =IF(ISBLANK('Список деталей'!G25),"",VLOOKUP('Список деталей'!G25,обозначениКромки,4,0)) | K17: =IF(ISBLANK('Список деталей'!H25),"",VLOOKUP('Список деталей'!H25,обозначениКромки,4,0)) | L17: =IF(ISBLANK('Список деталей'!I25),"",VLOOKUP('Список деталей'!I25,обозначениКромки,4,0)) | M17: =IF(ISBLANK('Список деталей'!Y25),"",('Список деталей'!Y25)) | N17: =IF(ISBLANK('Список деталей'!Z25),"",('Список деталей'!Z25)) | O17: =IF(ISBLANK('Список деталей'!AA25),"",('Список деталей'!AA25)) | P17: =IF(ISBLANK('Список деталей'!AB25),"",('Список деталей'!AB25)) | Q17: =VLOOKUP(IF(ISBLANK('Список деталей'!H25)=TRUE,7,'Список деталей'!H25),кромка,2,0)+VLOOKUP(IF(ISBLANK('Список деталей'!I25)=TRUE,7,'Список деталей'!I25),кромка,2,0)+'Список деталей'!C25 -> 0 | R17: =VLOOKUP(IF(ISBLANK('Список деталей'!F25)=TRUE,7,'Список деталей'!F25),кромка,2,0)+VLOOKUP(IF(ISBLANK('Список деталей'!G25)=TRUE,7,'Список деталей'!G25),кромка,2,0)+'Список деталей'!D25 -> 0 | S17: =IF('Список деталей'!H25="",0,1)+IF('Список деталей'!I25="",0,1)+'Список деталей'!C25 -> 0 | T17: =IF('Список деталей'!F25="",0,1)+IF('Список деталей'!G25="",0,1)+'Список деталей'!D25 -> 0 | U17: =IF(ISBLANK('Список деталей'!K25),"",'Список деталей'!K25) | V17: =IF(AND('Список деталей'!C25>849,'Список деталей'!D25>849)=TRUE,1*'Список деталей'!E25,"")
A18: =IF(ISNUMBER('Список деталей'!A26), 'Список деталей'!A26, "") -> 17 | B18: =IF(ISBLANK('Список деталей'!B26),"",'Список деталей'!B26) | C18: =IF(ISNUMBER('Список деталей'!C26), $W$4,"") | D18: =IF(ISNUMBER('Список деталей'!C26), 'Список деталей'!$I$4,"") | E18: =IF(ISNUMBER('Список деталей'!E26), 'Список деталей'!E26, "") | F18: =IF(ISNUMBER('Список деталей'!C26), 'Список деталей'!C26, "") | G18: =IF(ISNUMBER('Список деталей'!D26), 'Список деталей'!D26, "") | H18: =U18&" "&M18&" "&N18&" "&O18&" "&P18 | I18: =IF(ISBLANK('Список деталей'!F26),"",VLOOKUP('Список деталей'!F26,обозначениКромки,4,0)) | J18: =IF(ISBLANK('Список деталей'!G26),"",VLOOKUP('Список деталей'!G26,обозначениКромки,4,0)) | K18: =IF(ISBLANK('Список деталей'!H26),"",VLOOKUP('Список деталей'!H26,обозначениКромки,4,0)) | L18: =IF(ISBLANK('Список деталей'!I26),"",VLOOKUP('Список деталей'!I26,обозначениКромки,4,0)) | M18: =IF(ISBLANK('Список деталей'!Y26),"",('Список деталей'!Y26)) | N18: =IF(ISBLANK('Список деталей'!Z26),"",('Список деталей'!Z26)) | O18: =IF(ISBLANK('Список деталей'!AA26),"",('Список деталей'!AA26)) | P18: =IF(ISBLANK('Список деталей'!AB26),"",('Список деталей'!AB26)) | Q18: =VLOOKUP(IF(ISBLANK('Список деталей'!H26)=TRUE,7,'Список деталей'!H26),кромка,2,0)+VLOOKUP(IF(ISBLANK('Список деталей'!I26)=TRUE,7,'Список деталей'!I26),кромка,2,0)+'Список деталей'!C26 -> 0 | R18: =VLOOKUP(IF(ISBLANK('Список деталей'!F26)=TRUE,7,'Список деталей'!F26),кромка,2,0)+VLOOKUP(IF(ISBLANK('Список деталей'!G26)=TRUE,7,'Список деталей'!G26),кромка,2,0)+'Список деталей'!D26 -> 0 | S18: =IF('Список деталей'!H26="",0,1)+IF('Список деталей'!I26="",0,1)+'Список деталей'!C26 -> 0 | T18: =IF('Список деталей'!F26="",0,1)+IF('Список деталей'!G26="",0,1)+'Список деталей'!D26 -> 0 | U18: =IF(ISBLANK('Список деталей'!K26),"",'Список деталей'!K26) | V18: =IF(AND('Список деталей'!C26>849,'Список деталей'!D26>849)=TRUE,1*'Список деталей'!E26,"")
... A300: =IF(ISNUMBER('Список деталей'!A308), 'Список деталей'!A308, "") | B300: =IF(ISBLANK('Список деталей'!B308),"",'Список деталей'!B308) | C300: =IF(ISNUMBER('Список деталей'!C308), $W$4,"") | D300: =IF(ISNUMBER('Список деталей'!C308), 'Список деталей'!$I$4,"") | E300: =IF(ISNUMBER('Список деталей'!E308), 'Список деталей'!E308, "") | F300: =IF(ISNUMBER('Список деталей'!C308), 'Список деталей'!C308, "") | G300: =IF(ISNUMBER('Список деталей'!D308), 'Список деталей'!D308, "") | H300: =U300&" "&M300&" "&N300&" "&O300&" "&P300 | I300: =IF(ISBLANK('Список деталей'!F308),"",VLOOKUP('Список деталей'!F308,обозначениКромки,4,0)) | J300: =IF(ISBLANK('Список деталей'!G308),"",VLOOKUP('Список деталей'!G308,обозначениКромки,4,0)) | K300: =IF(ISBLANK('Список деталей'!H308),"",VLOOKUP('Список деталей'!H308,обозначениКромки,4,0)) | L300: =IF(ISBLANK('Список деталей'!I308),"",VLOOKUP('Список деталей'!I308,обозначениКромки,4,0)) | M300: =IF(ISBLANK('Список деталей'!Y308),"",('Список деталей'!Y308)) | N300: =IF(ISBLANK('Список деталей'!Z308),"",('Список деталей'!Z308)) | O300: =IF(ISBLANK('Список деталей'!AA308),"",('Список деталей'!AA308)) | P300: =IF(ISBLANK('Список деталей'!AB308),"",('Список деталей'!AB308)) | Q300: =VLOOKUP(IF(ISBLANK('Список деталей'!H308)=TRUE,7,'Список деталей'!H308),кромка,2,0)+VLOOKUP(IF(ISBLANK('Список деталей'!I308)=TRUE,7,'Список деталей'!I308),кромка,2,0)+'Список деталей'!C308 -> 0 | R300: =VLOOKUP(IF(ISBLANK('Список деталей'!F308)=TRUE,7,'Список деталей'!F308),кромка,2,0)+VLOOKUP(IF(ISBLANK('Список деталей'!G308)=TRUE,7,'Список деталей'!G308),кромка,2,0)+'Список деталей'!D308 -> 0 | S300: =IF('Список деталей'!H308="",0,1)+IF('Список деталей'!I308="",0,1)+'Список деталей'!C308 -> 0 | T300: =IF('Список деталей'!F308="",0,1)+IF('Список деталей'!G308="",0,1)+'Список деталей'!D308 -> 0 | U300: =IF(ISBLANK('Список деталей'!K308),"",'Список деталей'!K308) | V300: =IF(AND('Список деталей'!C308>849,'Список деталей'!D308>849)=TRUE,1*'Список деталей'!E308,"")

Sheet Список деталей
E1: Адрес: | F1: Новосибирск, ул. Станционная 59/2 | Z1: СКЛ= склейка | AB1: {=CEILING((SUMPRODUCT(--((ISNUMBER(SEARCH("докром",$K$10:$K$194))+ISNUMBER(SEARCH("косо",$K$10:$K$194)))>0),$C$10:$C$194,$E$10:$E$194)+500*SUMPRODUCT(--((ISNUMBER(SEARCH("R",$K$10:$K$194))+ISNUMBER(SEARCH("радиус",$K$10:$K$194)))>0),$E$10:$E$194))/1000,1.5)} -> 3
E2: Телефон: | F2: 8-913-720-13-70 | Z2: СКР=скрутка | AA2: ОБР = обратная сторона
A3: 1.10 | C3: =IF($K$6<>"",$K$6,"") | Z3: 0=0,4*19мм | AA3: ЛИЦ = лицевая сторона
A4: Клиент: | B4: ФИО | C4: Производитель | E4: ЛАМАРТИ | G4: толщина плиты | I4: 16 | Z4: 1=1*19мм | AA4: LED = подсветка врезная
A5: Декор | B5: лдсп фон бежевый | H5: ='KDT2'!W6 | Z5: 2=2*19мм
A6: Кромка: | B6: в цвет материала, иначе указываем в примечании | K6: {=IF(OR(SUMPRODUCT(--ISERROR('KDT2'!$A$1:$X$304))>0,$C$8<>"Длина (Х)",$D$8<>"Ширина (Y)",$E$8<>"Кол-во",$F$9<>"L1",$G$9<>"L2",$H$9<>"W1",$I$9<>"W2",$K$8<>"примечание"),"Бланк сломался - скачайте новый у нас на сайте","")} | Z6: вырез R2 кромим 1мм = вырез с 2мя радиусами который надо закромить
Z7: РПЛ 60*2шт = распилить на 2шт по 60мм
A8: №№ | B8: Название | C8: Длина (Х) | D8: Ширина (Y) | E8: Кол-во | F8: Длина L | H8: Ширина W | J8: Вращение | K8: примечание | M8: Вид кромки | Q8: Наличие кромки | U8: вращ | Y8: Паз L | AA8: Паз W
F9: L1 | G9: L2 | H9: W1 | I9: W2 | M9: у1 | N9: у2 | O9: х1 | P9: х2 | Q9: у1 | R9: у2 | S9: х1 | T9: х2 | Y9: L1 | Z9: L2 | AA9: W1 | AB9: W2
A10: 1 | B10: Крыша | C10: 100 | D10: 100 | E10: 1 | F10: 1 | G10: 1 | H10: 1 | I10: 0
A11: 2 | B11: стойка | C11: 699 | D11: 122 | E11: 2 | F11: 0 | G11: 1 | H11: 1 | I11: 1
A12: 3 | B12: дно | C12: 200 | D12: 400 | E12: 2 | F12: 1,0х35мм | G12: 0,4х35мм | H12: 1,0х35мм | I12: 1,0х35мм | K12: *32
A13: 4 | C13: 383 | D13: 554 | E13: 2 | F13: 0.4 | G13: 0.4 | H13: 0.4 | I13: 0.4
A14: 5 | C14: 367 | D14: 554 | E14: 2 | F14: 0.4 | G14: 0.4 | H14: 0.4 | I14: 0.4 | K14: радиус
A15: 6 | C15: 699 | D15: 155 | E15: 2 | F15: 1 | G15: 1 | H15: 1 | I15: 2
A16: 7 | C16: 155 | D16: 441 | E16: 2 | F16: 1 | G16: 0.4 | H16: 0.4 | I16: 0.4 | K16: Косарез с кром, чертёж
A17: 8 | C17: 439 | D17: 154 | E17: 1 | F17: 0.4 | G17: 0.4 | H17: 0.4 | I17: 0.4
A18: 9 | C18: 496 | D18: 126 | E18: 2 | F18: 1,0х35мм | G18: 0,4х35мм | K18: СКЛ 456*86-2шт
A19: 10 | C19: 439 | D19: 84 | E19: 1 | F19: 0.4 | G19: 0.4 | H19: 0.4 | I19: 0.4
A20: 11 | C20: 496 | D20: 172 | E20: 2 | F20: 1 | G20: 0.4 | H20: 0.4 | I20: 0.4 | K20: РПЛ до 56*2, докромить
A21: 12 | C21: 367 | D21: 69 | E21: 1 | F21: 0.4 | G21: 1 | H21: 0.4 | I21: 0.4
A22: 13 | C22: 100 | D22: 1000 | E22: 1
A23: 14
A24: 15
A25: 16
A26: 17
A27: 18
A28: 19
A29: 20
A30: 21
A31: 22
A32: 23
A33: 24
A34: 25
... A67: 58
A68: 59 | M68: =IF(ISBLANK(H68),0,VLOOKUP(H68,Справочник!$A$4:$C$11,2,0)) -> 0 | N68: =IF(ISBLANK(I68),0,VLOOKUP(I68,Справочник!$A$4:$C$11,2,0)) -> 0 | O68: =IF(ISBLANK(F68),0,VLOOKUP(F68,Справочник!$A$4:$C$11,2,0)) -> 0 | P68: =IF(ISBLANK(G68),0,VLOOKUP(G68,Справочник!$A$1:$C$11,2,0)) -> 0 | Q68: =IF(ISBLANK(H68),0,VLOOKUP(H68,Справочник!$A$4:$C$11,3,0)) -> 0 | R68: =IF(ISBLANK(I68),0,VLOOKUP(I68,Справочник!$A$4:$C$11,3,0)) -> 0 | S68: =IF(ISBLANK(F68),0,VLOOKUP(F68,Справочник!$A$4:$C$11,3,0)) -> 0 | T68: =IF(ISBLANK(G68),0,VLOOKUP(G68,Справочник!$A$4:$C$11,3,0)) -> 0 | U68: =IF(ISBLANK(J68),0,VLOOKUP(J68,Справочник!$E$4:$F$7,2,0)) -> 0 | V68: =((C68*2+D68*2)/1000)*E68 -> 0 | W68: =((C68+D68*2)/1000)*E68 -> 0
A69: 60 | M69: =IF(ISBLANK(H69),0,VLOOKUP(H69,Справочник!$A$4:$C$11,2,0)) -> 0 | N69: =IF(ISBLANK(I69),0,VLOOKUP(I69,Справочник!$A$4:$C$11,2,0)) -> 0 | O69: =IF(ISBLANK(F69),0,VLOOKUP(F69,Справочник!$A$4:$C$11,2,0)) -> 0 | P69: =IF(ISBLANK(G69),0,VLOOKUP(G69,Справочник!$A$1:$C$11,2,0)) -> 0 | Q69: =IF(ISBLANK(H69),0,VLOOKUP(H69,Справочник!$A$4:$C$11,3,0)) -> 0 | R69: =IF(ISBLANK(I69),0,VLOOKUP(I69,Справочник!$A$4:$C$11,3,0)) -> 0 | S69: =IF(ISBLANK(F69),0,VLOOKUP(F69,Справочник!$A$4:$C$11,3,0)) -> 0 | T69: =IF(ISBLANK(G69),0,VLOOKUP(G69,Справочник!$A$4:$C$11,3,0)) -> 0 | U69: =IF(ISBLANK(J69),0,VLOOKUP(J69,Справочник!$E$4:$F$7,2,0)) -> 0 | V69: =((C69*2+D69*2)/1000)*E69 -> 0 | W69: =((C69+D69*2)/1000)*E69 -> 0
A70: 61 | M70: =IF(ISBLANK(H70),0,VLOOKUP(H70,Справочник!$A$4:$C$11,2,0)) -> 0 | N70: =IF(ISBLANK(I70),0,VLOOKUP(I70,Справочник!$A$4:$C$11,2,0)) -> 0 | O70: =IF(ISBLANK(F70),0,VLOOKUP(F70,Справочник!$A$4:$C$11,2,0)) -> 0 | P70: =IF(ISBLANK(G70),0,VLOOKUP(G70,Справочник!$A$1:$C$11,2,0)) -> 0 | Q70: =IF(ISBLANK(H70),0,VLOOKUP(H70,Справочник!$A$4:$C$11,3,0)) -> 0 | R70: =IF(ISBLANK(I70),0,VLOOKUP(I70,Справочник!$A$4:$C$11,3,0)) -> 0 | S70: =IF(ISBLANK(F70),0,VLOOKUP(F70,Справочник!$A$4:$C$11,3,0)) -> 0 | T70: =IF(ISBLANK(G70),0,VLOOKUP(G70,Справочник!$A$4:$C$11,3,0)) -> 0 | U70: =IF(ISBLANK(J70),0,VLOOKUP(J70,Справочник!$E$4:$F$7,2,0)) -> 0 | V70: =((C70*2+D70*2)/1000)*E70 -> 0 | W70: =((C70+D70*2)/1000)*E70 -> 0
A71: 62 | M71: =IF(ISBLANK(H71),0,VLOOKUP(H71,Справочник!$A$4:$C$11,2,0)) -> 0 | N71: =IF(ISBLANK(I71),0,VLOOKUP(I71,Справочник!$A$4:$C$11,2,0)) -> 0 | O71: =IF(ISBLANK(F71),0,VLOOKUP(F71,Справочник!$A$4:$C$11,2,0)) -> 0 | P71: =IF(ISBLANK(G71),0,VLOOKUP(G71,Справочник!$A$1:$C$11,2,0)) -> 0 | Q71: =IF(ISBLANK(H71),0,VLOOKUP(H71,Справочник!$A$4:$C$11,3,0)) -> 0 | R71: =IF(ISBLANK(I71),0,VLOOKUP(I71,Справочник!$A$4:$C$11,3,0)) -> 0 | S71: =IF(ISBLANK(F71),0,VLOOKUP(F71,Справочник!$A$4:$C$11,3,0)) -> 0 | T71: =IF(ISBLANK(G71),0,VLOOKUP(G71,Справочник!$A$4:$C$11,3,0)) -> 0 | U71: =IF(ISBLANK(J71),0,VLOOKUP(J71,Справочник!$E$4:$F$7,2,0)) -> 0 | V71: =((C71*2+D71*2)/1000)*E71 -> 0 | W71: =((C71+D71*2)/1000)*E71 -> 0
A72: 63 | M72: =IF(ISBLANK(H72),0,VLOOKUP(H72,Справочник!$A$4:$C$11,2,0)) -> 0 | N72: =IF(ISBLANK(I72),0,VLOOKUP(I72,Справочник!$A$4:$C$11,2,0)) -> 0 | O72: =IF(ISBLANK(F72),0,VLOOKUP(F72,Справочник!$A$4:$C$11,2,0)) -> 0 | P72: =IF(ISBLANK(G72),0,VLOOKUP(G72,Справочник!$A$1:$C$11,2,0)) -> 0 | Q72: =IF(ISBLANK(H72),0,VLOOKUP(H72,Справочник!$A$4:$C$11,3,0)) -> 0 | R72: =IF(ISBLANK(I72),0,VLOOKUP(I72,Справочник!$A$4:$C$11,3,0)) -> 0 | S72: =IF(ISBLANK(F72),0,VLOOKUP(F72,Справочник!$A$4:$C$11,3,0)) -> 0 | T72: =IF(ISBLANK(G72),0,VLOOKUP(G72,Справочник!$A$4:$C$11,3,0)) -> 0 | U72: =IF(ISBLANK(J72),0,VLOOKUP(J72,Справочник!$E$4:$F$7,2,0)) -> 0 | V72: =((C72*2+D72*2)/1000)*E72 -> 0 | W72: =((C72+D72*2)/1000)*E72 -> 0
...

Sheet Справочник
A3: Кромка | B3: Код | E3: Вращение | H3: Приоритет
B4: 0 | C4: 0 | E4: не вращать | F4: 0 | H4: низкий | I4: 0 | K4: 7 | L4: 0 | N4: ЛАМАРТИ
A5: 0.4 | B5: 0 | C5: 1 | D5: ___ 04 ___ | E5: вращать | F5: 1 | H5: средний | I5: 1 | K5: 0.4 | L5: 0.5 | N5: НОРДЕКО
A6: 1 | B6: 8388608 | C6: 1 | D6: Х Х Х 1 Х Х Х | E6: вращать все этого признака | F6: 2 | H6: высокий | I6: 2 | K6: 1 | L6: 1 | N6: ТОМЛЕС
A7: 2 | B7: 128 | C7: 1 | D7: ■ ■ ■2■ ■ ■ | E7: вращать в группе | F7: 3 | K7: 2 | L7: 2 | N7: УВА
A8: 0,4х35мм | B8: 32768 | C8: 1 | D8: ___04 *35___ | K8: 0,4х35мм | L8: 0.5 | N8: ЭГГЕР
A9: 1,0х35мм | B9: 32896 | C9: 1 | D9: Х Х Х 1*35 Х Х Х | K9: 1,0х35мм | L9: 1 | N9: ЭКСТРАВЕРТ
A10: 2,0х35мм | B10: 32896 | C10: 1 | D10: ■ ■ ■2*35■ ■ ■ | K10: 2,0х35мм | L10: 2 | N10: АГТ
A11: 0 | B11: 0 | C11: 1 | D11: ___ 04 ___ | K11: 0 | L11: 0.5 | N11: КАСТОМОНУ
A12: 0,4 не в цвет | B12: 0 | C12: 1 | D12: ___04не в цвет ___ | K12: 0,4 не в цвет | L12: 0.5 | N12: УЛЬТРАДЕКОР
A13: 1 не в цвет | B13: 8388608 | C13: 1 | D13: Х Х Х 1не в цветХ Х Х | K13: 1 не в цвет | L13: 1 | N13: ЮГРА
A14: 2 не в цвет | B14: 128 | C14: 1 | D14: ■ ■ ■2не в цвет■ ■ ■ | K14: 2 не в цвет | L14: 2 | N14: РЕХАУ
A15: 0 не в цвет | B15: 0 | C15: 1 | D15: ___ 04не в цвет ___ | K15: 0 не в цвет | L15: 0.5 | N15: ЭТЕРНО
A16: 1*43мм | C16: 1 | D16: Х Х Х 1*43 Х Х Х | K16: 1*43мм | L16: 1
A17: 2*43 | C17: 1 | D17: ■ ■ ■2*43■ ■ ■ | K17: 2*43 | L17: 2
A18: 0,4х35мм не в цвет | B18: 32768 | C18: 1 | D18: ___ 04 *35 не в цвет___ | K18: 0,4х35мм не в цвет | L18: 0.5
A19: 1,0х35мм не в цвет | B19: 32896 | C19: 1 | D19: Х Х Х 1*35 не в цвет Х Х Х | K19: 1,0х35мм не в цвет | L19: 1
A20: 2,0х35мм не в цвет | B20: 32896 | C20: 1 | D20: ■ ■ ■2*35 не в цвет■ ■ ■ | K20: 2,0х35мм не в цвет | L20: 2

Sheet Площадь и кромка
A2: площадь деталей | H2: =CONCATENATE(ROUND(SUMPRODUCT('Список деталей'!C10:C108,'Список деталей'!D10:D108,'Список деталей'!E10:E108)/1000000,2)," кв.м") -> 2,05 кв.м
A3: 2750*1830 листов | H3: =ROUNDUP(ROUND(SUMPRODUCT('Список деталей'!C10:C108,'Список деталей'!D10:D108,'Список деталей'!E10:E108)/1000000,2)/5.0325,0) -> 1 | I3: ='Список деталей'!W109+(9*H3) -> 9
A4: 2800*2070 листов | H4: =ROUNDUP(ROUND(SUMPRODUCT('Список деталей'!C10:C108,'Список деталей'!D10:D108,'Список деталей'!E10:E108)/1000000,2)/5.796,0) -> 1 | I4: ='Список деталей'!W109+(10*H4) -> 10
A5: обгонка | H5: ='Список деталей'!V109/1.15 -> 0
A6: кол-во деталей | H6: =CONCATENATE(SUM('Список деталей'!E10:E108)," шт.") -> 21 шт.
A8: Кромка без запаса | I8: купить
A9: 0,4 мм | H9: =CONCATENATE(ROUND(1*(SUMPRODUCT((('Список деталей'!$F$10:$F$108=Справочник!A5)+('Список деталей'!$G$10:$G$108=Справочник!A5))*('Список деталей'!$C$10:$C$108)*('Список деталей'!$E$10:$E$108))+SUMPRODUCT((('Список деталей'!$H$10:$H$108=Справочник!A5)+('Список деталей'!$I$10:$I$108=Справочник!A5))*('Список деталей'!$D$10:$D$108)*('Список деталей'!$E$10:$E$108)))/1000,2)," м") -> 13,92 м | I9: =CONCATENATE(ROUND(1*(SUMPRODUCT((('Список деталей'!$F$10:$F$108=Справочник!A11)+('Список деталей'!$G$10:$G$108=Справочник!A11))*('Список деталей'!$C$10:$C$108)*('Список деталей'!$E$10:$E$108))+SUMPRODUCT((('Список деталей'!$H$10:$H$108=Справочник!A11)+('Список деталей'!$I$10:$I$108=Справочник!A11))*('Список деталей'!$D$10:$D$108)*('Список деталей'!$E$10:$E$108)))/1000,2)," м") -> 4,2 м
